Workbook

Sheet Instructions

Sheet निर्देश

Sheet Input
E2: EPS 1995 Pension - Input
E3: Developed by Mr. Neeraj Bhargava (9950826109) in consultation with Mr. Parveen Kohli (9810306699) & with technical support from Mr. C Ramasamy
E5: Please read Instructions given in INSTRUCTIONS sheet carefully before proceeding for filling Input Sheet, else the results may differ from Actuals
E7: Fill data from existing PPO for Verifying / Calculating "Ceiling Salary Pension" (Format for Dates : DD-MM-YYYY) | O7: Fill data for Calculating "Actual Salary Pension"
E8: Date of Birth | I8: 22386 | J8: Name | K8: VARRINDER KAUR RAINA | O8: Date of commencement of Actual Salary Pension (Format: DD-MM-YYYY)
E9: Date of Joining PF | I9: 29221 | J9: Non Contributory Period, if any (nos. in Days) | N9: 0
E10: Date of Exit | I10: 43586 | J10: Last month when full salary received | L10: 44287 | M10: Service Weightage (in years) | N10: 39
E11: Date of commencement of "Ceiling Amount Pension" | I11: 43586 | O11: 43586
E13: S No | F13: Financial Year | G13: Input data for Monthly PF'able salary
G14: Please fill PF'able Salary is considered like, 16th November to 30th November amount to be transferred in December month, December amount paid in January and likewise | O14: 01-12-1995 (16/11-30/11)
E15: 1 | F15: 1995-96 | G15: 34790 | H15: 34820 | I15: 34851 | J15: 34881 | K15: 34912 | L15: 34943 | M15: 34973 | N15: 35004 | O15: 35034 | P15: 35065 | Q15: 35096 | R15: 35125
G16: EPS-95 started from 16-11-1995
E17: 2 | F17: 1996-97 | G17: 35156 | H17: 35186 | I17: 35217 | J17: 35247 | K17: 35278 | L17: 35309 | M17: 35339 | N17: 35370 | O17: 35400 | P17: 35431 | Q17: 35462 | R17: 35490
E19: 3 | F19: 1997-98 | G19: 35521 | H19: 35551 | I19: 35582 | J19: 35612 | K19: 35643 | L19: 35674 | M19: 35704 | N19: 35735 | O19: 35765 | P19: 35796 | Q19: 35827 | R19: 35855
E21: 4 | F21: 1998-99 | G21: 35886 | H21: 35916 | I21: 35947 | J21: 35977 | K21: 36008 | L21: 36039 | M21: 36069 | N21: 36100 | O21: 36130 | P21: 36161 | Q21: 36192 | R21: 36220
E23: 5 | F23: 1999-2000 | G23: 36251 | H23: 36281 | I23: 36312 | J23: 36342 | K23: 36373 | L23: 36404 | M23: 36434 | N23: 36465 | O23: 36495 | P23: 36526 | Q23: 36557 | R23: 36586
E25: 6 | F25: 2000-01 | G25: 36617 | H25: 36647 | I25: 36678 | J25: 36708 | K25: 36739 | L25: 36770 | M25: 36800 | N25: 36831 | O25: 36861 | P25: 36892 | Q25: 36923 | R25: 36951
E27: 7 | F27: 2001-02 | G27: 36982 | H27: 37012 | I27: 37043 | J27: 37073 | K27: 37104 | L27: 37135 | M27: 37165 | N27: 37196 | O27: 37226 | P27: 37257 | Q27: 37288 | R27: 37316
E29: 8 | F29: 2002-03 | G29: 37347 | H29: 37377 | I29: 37408 | J29: 37438 | K29: 37469 | L29: 37500 | M29: 37530 | N29: 37561 | O29: 37591 | P29: 37622 | Q29: 37653 | R29: 37681
E31: 9 | F31: 2003-04 | G31: 37712 | H31: 37742 | I31: 37773 | J31: 37803 | K31: 37834 | L31: 37865 | M31: 37895 | N31: 37926 | O31: 37956 | P31: 37987 | Q31: 38018 | R31: 38047
E33: 10 | F33: 2004-05 | G33: 38078 | H33: 38108 | I33: 38139 | J33: 38169 | K33: 38200 | L33: 38231 | M33: 38261 | N33: 38292 | O33: 38322 | P33: 38353 | Q33: 38384 | R33: 38412
E35: 11 | F35: 2005-06 | G35: 38443 | H35: 38473 | I35: 38504 | J35: 38534 | K35: 38565 | L35: 38596 | M35: 38626 | N35: 38657 | O35: 38687 | P35: 38718 | Q35: 38749 | R35: 38777
E37: 12 | F37: 2006-07 | G37: 38808 | H37: 38838 | I37: 38869 | J37: 38899 | K37: 38930 | L37: 38961 | M37: 38991 | N37: 39022 | O37: 39052 | P37: 39083 | Q37: 39114 | R37: 39142
E39: 13 | F39: 2007-08 | G39: 39173 | H39: 39203 | I39: 39234 | J39: 39264 | K39: 39295 | L39: 39326 | M39: 39356 | N39: 39387 | O39: 39417 | P39: 39448 | Q39: 39479 | R39: 39508
E41: 14 | F41: 2008-09 | G41: 39539 | H41: 39569 | I41: 39600 | J41: 39630 | K41: 39661 | L41: 39692 | M41: 39722 | N41: 39753 | O41: 39783 | P41: 39814 | Q41: 39845 | R41: 39873
R42: 174178
E43: 15 | F43: 2009-10 | G43: 39904 | H43: 39934 | I43: 39965 | J43: 39995 | K43: 40026 | L43: 40057 | M43: 40087 | N43: 40118 | O43: 40148 | P43: 40179 | Q43: 40210 | R43: 40238
G44: 28963 | H44: 28963 | I44: 31813 | J44: 29841 | K44: 29841 | L44: 29841 | M44: 31064 | N44: 31064 | O44: 34721 | P44: 31052 | Q44: 31052 | R44: 31052
E45: 16 | F45: 2010-11 | G45: 40269 | H45: 40299 | I45: 40330 | J45: 40360 | K45: 40391 | L45: 40422 | M45: 40452 | N45: 40483 | O45: 40513 | P45: 40544 | Q45: 40575 | R45: 40603
G46: 38876 | H46: 33008 | I46: 33008 | J46: 33008 | K46: 33008 | L46: 35774 | M46: 41488 | N46: 36598 | O46: 36598 | P46: 36598 | Q46: 36598 | R46: 54870
E47: 17 | F47: 2011-12 | G47: 40634 | H47: 40664 | I47: 40695 | J47: 40725 | K47: 40756 | L47: 40787 | M47: 40817 | N47: 40848 | O47: 40878 | P47: 40909 | Q47: 40940 | R47: 40969
G48: 41140 | H48: 38112 | I48: 38112 | J48: 39260 | K48: 39260 | L48: 39260 | M48: 41080 | N48: 41080 | O48: 46540 | P48: 41080 | Q48: 41080 | R48: 41080
E49: 18 | F49: 2012-13 | G49: 41000 | H49: 41030 | I49: 41061 | J49: 41091 | K49: 41122 | L49: 41153 | M49: 41183 | N49: 41214 | O49: 41244 | P49: 41275 | Q49: 41306 | R49: 41334
G50: 42900 | H50: 42900 | I50: 48360 | J50: 44187 | K50: 44187 | L50: 44187 | M50: 46062 | N50: 51687 | O50: 46062 | P50: 46062 | Q50: 46062 | R50: 46062
E51: 19 | F51: 2013-14 | G51: 41365 | H51: 41395 | I51: 41426 | J51: 41456 | K51: 41487 | L51: 41518 | M51: 41548 | N51: 41579 | O51: 41609 | P51: 41640 | Q51: 41671 | R51: 41699
G52: 46062 | H52: 56772 | I52: 48204 | J52: 49662 | K52: 49662 | L52: 57939 | M52: 52421 | N52: 52421 | O52: 52421 | P52: 52421 | Q52: 52421 | R52: 52421
E53: 20 | F53: 2014-15 | G53: 41730 | H53: 41760 | I53: 41791 | J53: 41821 | K53: 41852 | L53: 41883 | M53: 41913 | N53: 41944 | O53: 41974 | P53: 42005 | Q53: 42036 | R53: 42064
G54: 63457 | H54: 55180 | I54: 55180 | J54: 56840 | K54: 56840 | L54: 58829 | M54: 58829 | N54: 62807 | O54: 58829 | P54: 58829 | Q54: 29415 | R54: 63031
E55: 21 | F55: 2015-16 | G55: 42095 | H55: 42125 | I55: 42156 | J55: 42186 | K55: 42217 | L55: 42248 | M55: 42278 | N55: 42309 | O55: 42339 | P55: 42370 | Q55: 42401 | R55: 42430
G56: 64921 | H56: 60535 | I56: 60535 | J56: 62366 | K56: 62366 | L56: 64123 | M56: 67637 | N56: 64123 | O56: 65263 | P56: 65203 | Q56: 65323 | R56: 65323
...

Sheet Pension Cal
A1: EPS 1995 Pension - "Ceiling Amount" & "Actual Salary" Pension Calculation
A2: Developed by Mr. Neeraj Bhargava (9950826109) in consultation with Mr. Parveen Kohli (9810306699) & with technical support from Mr. C Ramasamy
A4: Please read Instructions given in INSTRUCTIONS sheet carefully
A6: Name | C6: =Input!K8 -> VARRINDER KAUR RAINA | I6: Year | K6: Month | L6: Days | N6: Computation of Past Service Factor
A7: Date of Birth | I7: =YEAR(Input!I8) -> 1961 | K7: =MONTH(Input!I8) -> 4 | L7: =DAY(Input!I8) -> 15 | N7: Years of Past Service | V7: Salary <2500 | Y7: Salary >=2500
A8: Date of Joining PF | I8: =YEAR(Input!I9) -> 1980 | K8: =MONTH(Input!I9) -> 1 | L8: =DAY(Input!I9) -> 1 | N8: <= 11 Years | V8: 80 | Y8: 85
A9: Date of EPS Joining | F9: 35019 | I9: =YEAR(F9) -> 1995 | K9: =MONTH('Pension Cal'!F9) -> 11 | L9: =DAY('Pension Cal'!F9) -> 16 | N9: >11 Years & <=15 years | V9: 95 | Y9: 105
A10: Date of Change in Table B | F10: 39609 | I10: =YEAR(F10) -> 2008 | K10: =MONTH(F10) -> 6 | L10: =DAY(F10) -> 10 | N10: > 15 Years <= 20 years | V10: 120 | Y10: 135
A11: Date of Ceiling Change | F11: 41883 | I11: =YEAR(F11) -> 2014 | K11: =MONTH('Pension Cal'!F11) -> 9 | L11: =DAY('Pension Cal'!F11) -> 1 | N11: >20 years | V11: 150 | Y11: 170
A12: Date of Superannuation | F12: =DATE(I12,K12,L12) -> 43570 | I12: =I7+58 -> 2019 | K12: =K7 -> 4 | L12: =L7 -> 15 | N12: DERIVED VALUE FOR THE PAST SERVICE | V12: =IF(Q24=0,0,VLOOKUP(Q24,D58:E86,2,1)) -> 120 | Y12: =IF(Q24=0,0,VLOOKUP(Q24,D58:G86,4,1)) -> 135
A13: Date of Commencement of Ceiling Amount Pension | I13: =YEAR(Input!I11) -> 2019 | K13: =MONTH(Input!I11) -> 5 | L13: =DAY(Input!I11) -> 1 | N13: Past Service Factor (PSF) | Y13: =IF(Input!L10<=2500,V12,Y12) -> 135
A14: Date of Commencement of Actual Salary Pension | I14: =YEAR(Input!O11) -> 2019 | K14: =MONTH(Input!O11) -> 5 | L14: =DAY(Input!O11) -> 1
A16: Additional Details: | E16: Ceiling upto 31.08.2014 | I16: Ceiling from 01.09.2014 | N16: Computation of Table B Factor (GSR 134E / GSR 438E)
N17: Service years from 16-11-1995 to Date of Exit | V17: DOE<10.06.2008 | Y17: DOE>=10.06.2008
A18: On Ceiling pension | E18: 6500 | I18: 15000 | N18: Less than | Q18: =M27/360 -> 23.458333 | S18: Years | V18: =IF(M24=0,0,VLOOKUP(Q18,Y58:Z92,2,1)) -> 9.39 | Y18: =IF(M24=0,0,VLOOKUP(Q18,N58:Q92,4,1)) -> 6.101
A19: On Actual pension | E19: No cap | I19: No cap | N19: Table B Value | Y19: =IF(Input!I10<=F10,V18,Y18) -> 6.101
A21: EPS Para Ref. | E21: Details | M21: No. of days | Q21: Years | T21: Months | W21: Days
A22: 9. Eligible Service | E22: Total Service | M22: =DAYS360(Input!I9,Input!I10) -> 14160 | Q22: =INT(M22/360) -> 39 | T22: =INT((M22/360-Q22)*12) -> 4 | W22: =M22-Q22*360-T22*30 -> 0
E23: Eligible Service | Q23: =IF(2*(M22/360)>(2*Q22+1),(Q22+1),(M22/360)) -> 39.333333 | T23: 0 | W23: 0
E24: Past Service (service upto 15.11.1995) | M24: =IF(Input!I9=0,0,IF(Input!I9>=F9,0,DAYS360(Input!I9,F9))) -> 5715 | Q24: =INT(M24/360) -> 15 | T24: =INT((M24/360-Q24)*12) -> 10 | W24: =M24-Q24*360-T24*30 -> 15
A25: 10 (1) Pensionable Service | E25: Service from 16-11-1995 to 31-08-2014 or DoE | M25: =IF(Input!I9=0,0,IF(Input!I9>=F9,DAYS360(Input!I9,F11),IF(Input!I10<='Pension Cal'!F11,DAYS360('Pension Cal'!F9,Input!I10),DAYS360('Pension Cal'!F9,'Pension Cal'!F11)))) -> 6765 | Q25: =INT(M25/360) -> 18 | T25: =INT((M25/360-Q25)*12) -> 9 | W25: =(M25-Q25*360-T25*30) -> 15
E26: Service from 01-09-2014 to Date of Exit | M26: =IF(Input!I11<='Pension Cal'!F11,0,DAYS360('Pension Cal'!F11,Input!I11)) -> 1680 | Q26: =INT(M26/360) -> 4 | T26: =INT((M26/360-Q26)*12) -> 8 | W26: =(M26-Q26*360-T26*30) -> 0
E27: Contribution received for the period | M27: =SUM(M25:M26) -> 8445 | Q27: =INT(M27/360) -> 23 | T27: =INT((M27/360-Q27)*12) -> 5 | W27: =M27-Q27*360-T27*30 -> 15
A28: 10 (2) Weightage of 2 years | E28: Weightage Service | M28: =IF(Input!N10=2,720,0) -> 0 | Q28: =INT(M28/360) -> 0 | T28: =INT((M28/360-Q28)*12) -> 0 | W28: =M28-Q28*360-T28*30 -> 0
E29: Non contributory period | M29: =Input!N9 -> 0 | Q29: =INT(M29/360) -> 0 | T29: =INT((M29/360-Q29)*12) -> 0 | W29: =M29-Q29*360-T29*30 -> 0
E30: Total Pensionable Service considering 6,500 limit | M30: =M25+M28-M29 -> 6765 | Q30: =Q25+Q28-Q29 -> 18 | T30: =T25+T28-T29 -> 9 | W30: =W25+W28-W29 -> 15
E31: Total Pensionable Service considering 15,000 limit | M31: =M27+M28-M29 -> 8445 | Q31: =Q27+Q28-Q29 -> 23 | T31: =T27+T28-T29 -> 5 | W31: =W27+W28-W29 -> 15
A32: Early Exit Cal. | E32: Diff in Superannuation & exit dates | M32: =IF(Input!I11=0,0,ABS(DAYS360(F12,Input!I11))) -> 16 | Q32: =INT(M32/360) -> 0 | T32: =INT((M32/360-Q32)*12) -> 0 | W32: =M32-Q32*360-T32*30 -> 16
M34: Ceiling Salary Pension | V34: Actual Salary Pension
A35: 11. Pensionable Salary etc. | H35: Pensionable Service (Days) | M35: Pensionable Salary | O35: Past Service Factor | R35: Table B | V35: Pensionable Salary | X35: Past Service Factor | AA35: Table B
V36: Pre 01-09-2014 retirees | W36: Post 01-09-2014 retirees
A37: For Normal / Higher Pension | H37: =M30 -> 6765 | M37: =IF(Input!I10=0,0,IF(Input!I10<=F11,E18,((Q26*12+T26+W26/30)*I18+(60-(Q26*12+T26+W26/30))*E18)/((5*360)/30))) -> 14433.333 | O37: =Y13 -> 135 | R37: =Y19 -> 6.101 | V37: =IF(Input!I10>'Pension Cal'!F11,0,AVERAGE(('Amount Cal'!G202:'Amount Cal'!R202))) -> 0 | W37: =IF(Input!I10<='Pension Cal'!F11,0,AVERAGE(('Amount Cal'!G202:'Amount Cal'!R202),('Amount Cal'!G204:'Amount Cal'!R204),('Amount Cal'!G206:'Amount Cal'!R206),('Amount Cal'!G208:'Amount Cal'!R208),('Amount Cal'!G210:'Amount Cal'!R210))) -> 86909.967 | X37: =Y13 -> 135 | AA37: =Y19 -> 6.101
E39: Break up Details | M39: Pension Calculations
M40: Ceiling Salary Pension | R40: Actual Salary Pension
A42: 12 (1) (a) Monthly Pension | E42: For Actual Service @ 6,500/- | M42: =IF('Amount Cal'!G202=0,0,IF('Amount Cal'!G202<=E18,(M31/360)*(E18/70),(M30/360)*(E18/70))) -> 1744.9405 | R42: =IF(Input!I10<'Pension Cal'!F11,(V37/70)*(H37/360),(W37/70)*(H37/360)) -> 23331.187
E43: For Actual Service @ 15,000/- | M43: =IF('Amount Cal'!G202=0,0,IF('Amount Cal'!G202>E18,M37/70*M26/360,0)) -> 962.22222
E44: For Past Service (Table A x Table B) | M44: =IF('Amount Cal'!G202=0,0,IF(Input!I9=0,0,O37*R37)) -> 823.635 | R44: =IF('Amount Cal'!G202=0,0,X37*AA37) -> 823.635
E45: Total | M45: =M42+M43+M44 -> 3530.7977 | R45: =R42+R44 -> 24154.822
E46: Superannuation Pension | M46: =ROUND(M45,0) -> 3531 | R46: =ROUND(R45,0) -> 24155
E47: Spouse Pension (after Death) | M47: =M46/2 -> 1765.5 | R47: =R46/2 -> 12077.5
...

Sheet Amount Cal
A1: Month | B1: Salary | D1: EPS 1995 Pension - Differential Amount and Interest Payable Calculations
A2: 34790 | D2: Developed by Mr. Neeraj Bhargava (9950826109) in consultation with Mr. Parveen Kohli (9810306699) & with technical support from Mr. C Ramasamy
A3: 34820
A4: 34851 | D4: Please read Instructions given in INSTRUCTIONS sheet carefully
A5: 34881
A6: 34912 | D6: Name | G6: Wage Ceiling | H6: From | I6: To | J6: Ceiling | K6: Max Contribution | M6: Wage Ceiling | N6: From | O6: To | P6: Ceiling | Q6: Max Contribution | S6: Wage Ceiling | T6: From | U6: Ceiling | V6: Max Contribution
A7: 34943 | D7: =Input!K8 -> VARRINDER KAUR RAINA | G7: Ceiling 1 | H7: 34344 | I7: 31-05-2001 | J7: 5000 | K7: 417 | M7: Ceiling 2 | N7: 37043 | O7: 31-08-2014 | P7: 6500 | Q7: 541 | S7: Ceiling 3 | T7: 41883 | U7: 15000 | V7: 1250
A8: 34973
A9: 35004 | D9: Date of Exit | J9: Date of commencement of "Ceiling Amount Pension" | Q9: Date of commencement of "Actual Salary Pension"
A10: 35034 | B10: =Input!O16 -> 0 | D10: Year | E10: Month | F10: Days | J10: Year | K10: Month | L10: Days | Q10: Year | R10: Month | S10: Days
A11: 35065 | B11: =Input!P16 -> 0 | D11: =IF(Input!I10=0,0,YEAR(Input!I10)) -> 2019 | E11: =IF(Input!I10=0,0,MONTH(Input!I10)) -> 5 | F11: =IF(Input!I10=0,0,DAY(Input!I10)) -> 1 | G11: =IF(Input!I10=0,1,DATE(D11,E11,1)) -> 43586 | H11: =E11+1 -> 6 | I11: =IF(Input!I10=0,1,DATE(D11,H11,1)) -> 43617 | J11: =IF(Input!I11=0,0,YEAR(Input!I11)) -> 2019 | K11: =IF(Input!I11=0,0,MONTH(Input!I11)) -> 5 | L11: =IF(Input!I11=0,0,DAY(Input!I11)) -> 1 | M11: =IF(Input!I11=0,1,DATE(J11,K11,1)) -> 43586 | N11: =K11+1 -> 6 | O11: =IF(Input!I11=0,1,DATE(J11,N11,1)) -> 43617 | Q11: =IF(Input!O11=0,0,YEAR(Input!O11)) -> 2019 | R11: =IF(Input!O11=0,0,MONTH(Input!O11)) -> 5 | S11: =IF(Input!O11=0,0,DAY(Input!O11)) -> 1 | T11: =IF(Input!O11=0,1,DATE(Q11,R11,1)) -> 43586 | U11: =R11-1 -> 4 | V11: =IF(Input!O11=0,1,DATE(Q11,U11,1)) -> 43556
A12: 35096 | B12: =Input!Q16 -> 0
A13: 35125 | B13: =Input!R16 -> 0 | D13: S No | E13: Financial Year & Rate of Interest | F13: Month | G13: April | H13: May | I13: June | J13: July | K13: August | L13: September | M13: October | N13: November | O13: December | P13: January | Q13: February | R13: March | S13: Total | T13: Differential Amount to be paid
A14: 35156 | B14: =Input!G$18 -> 0 | T14: Contribution | U14: Interest | V14: Total
A15: 35186 | B15: =Input!H$18 -> 0 | D15: 1 | E15: 1995-96 | F15: PF'able Salary | O15: 35034 | P15: 35065 | Q15: 35096 | R15: 35125 | S15: =SUM(Input!O16:R16) -> 0
A16: 35217 | B16: =Input!I$18 -> 0 | F16: 8.33% of PF'able Salary | O16: =IF(Input!O16=0,0,INT((Input!O16*8.33/100)+0.5)) -> 0 | P16: =IF(Input!P16=0,0,INT((Input!P16*8.33/100)+0.5)) -> 0 | Q16: =IF(Input!Q16=0,0,INT((Input!Q16*8.33/100)+0.5)) -> 0 | R16: =IF(Input!R16=0,0,INT((Input!R16*8.33/100)+0.5)) -> 0 | S16: =SUM(O16:R16) -> 0
A17: 35247 | B17: =Input!J$18 -> 0 | F17: Pension contribution (on ceiling) | O17: =IF(2*Input!O16<=$J$7,INT((Input!O16*8.33%)+0.5),INT(($J$7*8.33%)/2+0.5)) -> 0 | P17: =IF(Input!P16<=$J$7,INT((Input!P16*8.33%)+0.5),INT(($J$7*8.33%)+0.5)) -> 0 | Q17: =IF(Input!Q16<=$J$7,INT((Input!Q16*8.33%)+0.5),INT(($J$7*8.33%)+0.5)) -> 0 | R17: =IF(Input!R16<=$J$7,INT((Input!R16*8.33%)+0.5),INT(($J$7*8.33%)+0.5)) -> 0 | S17: =SUM(O17:R17) -> 0
A18: 35278 | B18: =Input!K$18 -> 0 | F18: Addl Amount Payable on PF'able Salary | O18: =IF(O16-O17<=0,0,O16-O17) -> 0 | P18: =IF(P16-P17<=0,0,P16-P17) -> 0 | Q18: =IF(Q16-Q17<=0,0,Q16-Q17) -> 0 | R18: =IF(R16-R17<=0,0,R16-R17) -> 0 | S18: =SUM(O18:R18) -> 0
A19: 35309 | B19: =Input!L$18 -> 0 | E19: Interest rate | F19: Progressive balance | O19: =IF(O15=0,0,IF($T$11<=Input!O14,0,N18+N19)) -> 0 | P19: =IF(P15=0,0,IF($T$11<=Input!P15,0,O18+O19)) -> 0 | Q19: =IF(Q15=0,0,IF($T$11<=Input!Q15,0,P18+P19)) -> 0 | R19: =IF(R15=0,0,IF($T$11<=Input!R15,0,Q18+Q19)) -> 0 | T19: =SUM(O18:R18) -> 0 | U19: =SUM(P20:R20) -> 0 | V19: =SUM(T19,U19) -> 0
A20: 35339 | B20: =Input!M$18 -> 0 | E20: 0.12 | F20: Interest amount | O20: =O19/12*$E20 -> 0 | P20: =P19/12*$E20 -> 0 | Q20: =Q19/12*$E20 -> 0 | R20: =R19/12*$E20 -> 0 | S20: =SUM(O20:R20) -> 0 | T20: =SUM(T19) -> 0 | U20: =SUM(U19) -> 0 | V20: =SUM(V19) -> 0
A21: 35370 | B21: =Input!N$18 -> 0 | D21: 2 | E21: 1996-97 | F21: PF'able Salary | G21: 35156 | H21: 35186 | I21: 35217 | J21: 35247 | K21: 35278 | L21: 35309 | M21: 35339 | N21: 35370 | O21: 35400 | P21: 35431 | Q21: 35462 | R21: 35490 | S21: =SUM(Input!G18:R18) -> 0
A22: 35400 | B22: =Input!O$18 -> 0 | F22: 8.33% of PF'able Salary | G22: =IF(Input!G18=0,0,INT((Input!G18*8.33/100)+0.5)) -> 0 | H22: =IF(Input!H18=0,0,INT((Input!H18*8.33/100)+0.5)) -> 0 | I22: =IF(Input!I18=0,0,INT((Input!I18*8.33/100)+0.5)) -> 0 | J22: =IF(Input!J18=0,0,INT((Input!J18*8.33/100)+0.5)) -> 0 | K22: =IF(Input!K18=0,0,INT((Input!K18*8.33/100)+0.5)) -> 0 | L22: =IF(Input!L18=0,0,INT((Input!L18*8.33/100)+0.5)) -> 0 | M22: =IF(Input!M18=0,0,INT((Input!M18*8.33/100)+0.5)) -> 0 | N22: =IF(Input!N18=0,0,INT((Input!N18*8.33/100)+0.5)) -> 0 | ... R22: =IF(Input!R18=0,0,INT((Input!R18*8.33/100)+0.5)) -> 0 | S22: =SUM(G22:R22) -> 0
A23: 35431 | B23: =Input!P$18 -> 0 | F23: Pension contribution (on ceiling) | G23: =IF(Input!G18<=$J$7,INT((Input!G18*8.33%)+0.5),INT(($J$7*8.33%)+0.5)) -> 0 | H23: =IF(Input!H18<=$J$7,INT((Input!H18*8.33%)+0.5),INT(($J$7*8.33%)+0.5)) -> 0 | I23: =IF(Input!I18<=$J$7,INT((Input!I18*8.33%)+0.5),INT(($J$7*8.33%)+0.5)) -> 0 | J23: =IF(Input!J18<=$J$7,INT((Input!J18*8.33%)+0.5),INT(($J$7*8.33%)+0.5)) -> 0 | K23: =IF(Input!K18<=$J$7,INT((Input!K18*8.33%)+0.5),INT(($J$7*8.33%)+0.5)) -> 0 | L23: =IF(Input!L18<=$J$7,INT((Input!L18*8.33%)+0.5),INT(($J$7*8.33%)+0.5)) -> 0 | M23: =IF(Input!M18<=$J$7,INT((Input!M18*8.33%)+0.5),INT(($J$7*8.33%)+0.5)) -> 0 | N23: =IF(Input!N18<=$J$7,INT((Input!N18*8.33%)+0.5),INT(($J$7*8.33%)+0.5)) -> 0 | ... R23: =IF(Input!R18<=$J$7,INT((Input!R18*8.33%)+0.5),INT(($J$7*8.33%)+0.5)) -> 0 | S23: =SUM(G23:R23) -> 0
A24: 35462 | B24: =Input!Q$18 -> 0 | F24: Addl Amount Payable on PF'able Salary | G24: =IF(G22-G23<=0,0,G22-G23) -> 0 | H24: =IF(H22-H23<=0,0,H22-H23) -> 0 | I24: =IF(I22-I23<=0,0,I22-I23) -> 0 | J24: =IF(J22-J23<=0,0,J22-J23) -> 0 | K24: =IF(K22-K23<=0,0,K22-K23) -> 0 | L24: =IF(L22-L23<=0,0,L22-L23) -> 0 | M24: =IF(M22-M23<=0,0,M22-M23) -> 0 | N24: =IF(N22-N23<=0,0,N22-N23) -> 0 | ... R24: =IF(R22-R23<=0,0,R22-R23) -> 0 | S24: =SUM(G24:R24) -> 0
A25: 35490 | B25: =Input!R$18 -> 0 | E25: Interest rate | F25: Progressive balance | G25: =IF(G21=0,0,IF($T$11<=Input!G17,0,R18+R19+U19)) -> 0 | H25: =IF(H21=0,0,IF($T$11<=Input!H17,0,G24+G25)) -> 0 | I25: =IF(I21=0,0,IF($T$11<=Input!I17,0,H24+H25)) -> 0 | J25: =IF(J21=0,0,IF($T$11<=Input!J17,0,I24+I25)) -> 0 | K25: =IF(K21=0,0,IF($T$11<=Input!K17,0,J24+J25)) -> 0 | L25: =IF(L21=0,0,IF($T$11<=Input!L17,0,K24+K25)) -> 0 | M25: =IF(M21=0,0,IF($T$11<=Input!M17,0,L24+L25)) -> 0 | N25: =IF(N21=0,0,IF($T$11<=Input!N17,0,M24+M25)) -> 0 | O25: =IF(O21=0,0,IF($T$11<=Input!O17,0,N24+N25)) -> 0 | ... R25: =IF(R21=0,0,IF($T$11<=Input!R17,0,Q24+Q25)) -> 0 | T25: =SUM(G24:R24) -> 0 | U25: =SUM(G26:R26) -> 0 | V25: =SUM(T25,U25) -> 0
A26: 35521 | B26: =Input!G$20 -> 0 | E26: 0.12 | F26: Interest amount | G26: =G25/12*$E26 -> 0 | H26: =H25/12*$E26 -> 0 | I26: =I25/12*$E26 -> 0 | J26: =J25/12*$E26 -> 0 | K26: =K25/12*$E26 -> 0 | L26: =L25/12*$E26 -> 0 | M26: =M25/12*$E26 -> 0 | N26: =N25/12*$E26 -> 0 | ... R26: =R25/12*$E26 -> 0 | S26: =SUM(G26:R26) -> 0 | T26: =SUM(T19,T25) -> 0 | U26: =SUM(U19,U25) -> 0 | V26: =SUM(V19,V25) -> 0
A27: 35551 | B27: =Input!H$20 -> 0 | D27: 3 | E27: 1997-98 | F27: PF'able Salary | G27: 35521 | H27: 35551 | I27: 35582 | J27: 35612 | K27: 35643 | L27: 35674 | M27: 35704 | N27: 35735 | O27: 35765 | P27: 35796 | Q27: 35827 | R27: 35855 | S27: =SUM(Input!G20:R20) -> 0
A28: 35582 | B28: =Input!I$20 -> 0 | F28: 8.33% of PF'able Salary | G28: =IF(Input!G20=0,0,INT((Input!G20*8.33/100)+0.5)) -> 0 | H28: =IF(Input!H20=0,0,INT((Input!H20*8.33/100)+0.5)) -> 0 | I28: =IF(Input!I20=0,0,INT((Input!I20*8.33/100)+0.5)) -> 0 | J28: =IF(Input!J20=0,0,INT((Input!J20*8.33/100)+0.5)) -> 0 | K28: =IF(Input!K20=0,0,INT((Input!K20*8.33/100)+0.5)) -> 0 | L28: =IF(Input!L20=0,0,INT((Input!L20*8.33/100)+0.5)) -> 0 | M28: =IF(Input!M20=0,0,INT((Input!M20*8.33/100)+0.5)) -> 0 | N28: =IF(Input!N20=0,0,INT((Input!N20*8.33/100)+0.5)) -> 0 | ... R28: =IF(Input!R20=0,0,INT((Input!R20*8.33/100)+0.5)) -> 0 | S28: =SUM(G28:R28) -> 0
A29: 35612 | B29: =Input!J$20 -> 0 | F29: Pension contribution (on ceiling) | G29: =IF(Input!G20<=$J$7,INT((Input!G20*8.33%)+0.5),INT(($J$7*8.33%)+0.5)) -> 0 | H29: =IF(Input!H20<=$J$7,INT((Input!H20*8.33%)+0.5),INT(($J$7*8.33%)+0.5)) -> 0 | I29: =IF(Input!I20<=$J$7,INT((Input!I20*8.33%)+0.5),INT(($J$7*8.33%)+0.5)) -> 0 | J29: =IF(Input!J20<=$J$7,INT((Input!J20*8.33%)+0.5),INT(($J$7*8.33%)+0.5)) -> 0 | K29: =IF(Input!K20<=$J$7,INT((Input!K20*8.33%)+0.5),INT(($J$7*8.33%)+0.5)) -> 0 | L29: =IF(Input!L20<=$J$7,INT((Input!L20*8.33%)+0.5),INT(($J$7*8.33%)+0.5)) -> 0 | M29: =IF(Input!M20<=$J$7,INT((Input!M20*8.33%)+0.5),INT(($J$7*8.33%)+0.5)) -> 0 | N29: =IF(Input!N20<=$J$7,INT((Input!N20*8.33%)+0.5),INT(($J$7*8.33%)+0.5)) -> 0 | ... R29: =IF(Input!R20<=$J$7,INT((Input!R20*8.33%)+0.5),INT(($J$7*8.33%)+0.5)) -> 0 | S29: =SUM(G29:R29) -> 0
A30: 35643 | B30: =Input!K$20 -> 0 | F30: Addl Amount Payable on PF'able Salary | G30: =IF(G28-G29<=0,0,G28-G29) -> 0 | H30: =IF(H28-H29<=0,0,H28-H29) -> 0 | I30: =IF(I28-I29<=0,0,I28-I29) -> 0 | J30: =IF(J28-J29<=0,0,J28-J29) -> 0 | K30: =IF(K28-K29<=0,0,K28-K29) -> 0 | L30: =IF(L28-L29<=0,0,L28-L29) -> 0 | M30: =IF(M28-M29<=0,0,M28-M29) -> 0 | N30: =IF(N28-N29<=0,0,N28-N29) -> 0 | ... R30: =IF(R28-R29<=0,0,R28-R29) -> 0 | S30: =SUM(G30:R30) -> 0
A31: 35674 | B31: =Input!L$20 -> 0 | E31: Interest rate | F31: Progressive balance | G31: =IF(G27=0,0,IF($T$11<=Input!G19,0,R24+R25+U25)) -> 0 | H31: =IF(H27=0,0,IF($T$11<=Input!H19,0,G30+G31)) -> 0 | I31: =IF(I27=0,0,IF($T$11<=Input!I19,0,H30+H31)) -> 0 | J31: =IF(J27=0,0,IF($T$11<=Input!J19,0,I30+I31)) -> 0 | K31: =IF(K27=0,0,IF($T$11<=Input!K19,0,J30+J31)) -> 0 | L31: =IF(L27=0,0,IF($T$11<=Input!L19,0,K30+K31)) -> 0 | M31: =IF(M27=0,0,IF($T$11<=Input!M19,0,L30+L31)) -> 0 | N31: =IF(N27=0,0,IF($T$11<=Input!N19,0,M30+M31)) -> 0 | O31: =IF(O27=0,0,IF($T$11<=Input!O19,0,N30+N31)) -> 0 | ... R31: =IF(R27=0,0,IF($T$11<=Input!R19,0,Q30+Q31)) -> 0 | T31: =SUM(G30:R30) -> 0 | U31: =SUM(G32:R32) -> 0 | V31: =SUM(T31,U31) -> 0
A32: 35704 | B32: =Input!M$20 -> 0 | E32: 0.12 | F32: Interest amount | G32: =G31/12*$E32 -> 0 | H32: =H31/12*$E32 -> 0 | I32: =I31/12*$E32 -> 0 | J32: =J31/12*$E32 -> 0 | K32: =K31/12*$E32 -> 0 | L32: =L31/12*$E32 -> 0 | M32: =M31/12*$E32 -> 0 | N32: =N31/12*$E32 -> 0 | ... R32: =R31/12*$E32 -> 0 | S32: =SUM(G32:R32) -> 0 | T32: =SUM(T19,T25,T31) -> 0 | U32: =SUM(U19,U25,U31) -> 0 | V32: =SUM(V19,V25,V31) -> 0
A33: 35735 | B33: =Input!N$20 -> 0 | D33: 4 | E33: 1998-99 | F33: PF'able Salary | G33: 35886 | H33: 35916 | I33: 35947 | J33: 35977 | K33: 36008 | L33: 36039 | M33: 36069 | N33: 36100 | O33: 36130 | P33: 36161 | Q33: 36192 | R33: 36220 | S33: =SUM(Input!G22:R22) -> 0
A34: 35765 | B34: =Input!O$20 -> 0 | F34: 8.33% of PF'able Salary | G34: =IF(Input!G22=0,0,INT((Input!G22*8.33/100)+0.5)) -> 0 | H34: =IF(Input!H22=0,0,INT((Input!H22*8.33/100)+0.5)) -> 0 | I34: =IF(Input!I22=0,0,INT((Input!I22*8.33/100)+0.5)) -> 0 | J34: =IF(Input!J22=0,0,INT((Input!J22*8.33/100)+0.5)) -> 0 | K34: =IF(Input!K22=0,0,INT((Input!K22*8.33/100)+0.5)) -> 0 | L34: =IF(Input!L22=0,0,INT((Input!L22*8.33/100)+0.5)) -> 0 | M34: =IF(Input!M22=0,0,INT((Input!M22*8.33/100)+0.5)) -> 0 | N34: =IF(Input!N22=0,0,INT((Input!N22*8.33/100)+0.5)) -> 0 | ... R34: =IF(Input!R22=0,0,INT((Input!R22*8.33/100)+0.5)) -> 0 | S34: =SUM(G34:R34) -> 0
A35: 35796 | B35: =Input!P$20 -> 0 | F35: Pension contribution (on ceiling) | G35: =IF(Input!G22<=$J$7,INT((Input!G22*8.33%)+0.5),INT(($J$7*8.33%)+0.5)) -> 0 | H35: =IF(Input!H22<=$J$7,INT((Input!H22*8.33%)+0.5),INT(($J$7*8.33%)+0.5)) -> 0 | I35: =IF(Input!I22<=$J$7,INT((Input!I22*8.33%)+0.5),INT(($J$7*8.33%)+0.5)) -> 0 | J35: =IF(Input!J22<=$J$7,INT((Input!J22*8.33%)+0.5),INT(($J$7*8.33%)+0.5)) -> 0 | K35: =IF(Input!K22<=$J$7,INT((Input!K22*8.33%)+0.5),INT(($J$7*8.33%)+0.5)) -> 0 | L35: =IF(Input!L22<=$J$7,INT((Input!L22*8.33%)+0.5),INT(($J$7*8.33%)+0.5)) -> 0 | M35: =IF(Input!M22<=$J$7,INT((Input!M22*8.33%)+0.5),INT(($J$7*8.33%)+0.5)) -> 0 | N35: =IF(Input!N22<=$J$7,INT((Input!N22*8.33%)+0.5),INT(($J$7*8.33%)+0.5)) -> 0 | ... R35: =IF(Input!R22<=$J$7,INT((Input!R22*8.33%)+0.5),INT(($J$7*8.33%)+0.5)) -> 0 | S35: =SUM(G35:R35) -> 0
A36: 35827 | B36: =Input!Q$20 -> 0 | F36: Addl Amount Payable on PF'able Salary | G36: =IF(G34-G35<=0,0,G34-G35) -> 0 | H36: =IF(H34-H35<=0,0,H34-H35) -> 0 | I36: =IF(I34-I35<=0,0,I34-I35) -> 0 | J36: =IF(J34-J35<=0,0,J34-J35) -> 0 | K36: =IF(K34-K35<=0,0,K34-K35) -> 0 | L36: =IF(L34-L35<=0,0,L34-L35) -> 0 | M36: =IF(M34-M35<=0,0,M34-M35) -> 0 | N36: =IF(N34-N35<=0,0,N34-N35) -> 0 | ... R36: =IF(R34-R35<=0,0,R34-R35) -> 0 | S36: =SUM(G36:R36) -> 0
A37: 35855 | B37: =Input!R$20 -> 0 | E37: Interest rate | F37: Progressive balance | G37: =IF(G33=0,0,IF($T$11<=Input!G21,0,R30+R31+U31)) -> 0 | H37: =IF(H33=0,0,IF($T$11<=Input!H21,0,G36+G37)) -> 0 | I37: =IF(I33=0,0,IF($T$11<=Input!I21,0,H36+H37)) -> 0 | J37: =IF(J33=0,0,IF($T$11<=Input!J21,0,I36+I37)) -> 0 | K37: =IF(K33=0,0,IF($T$11<=Input!K21,0,J36+J37)) -> 0 | L37: =IF(L33=0,0,IF($T$11<=Input!L21,0,K36+K37)) -> 0 | M37: =IF(M33=0,0,IF($T$11<=Input!M21,0,L36+L37)) -> 0 | N37: =IF(N33=0,0,IF($T$11<=Input!N21,0,M36+M37)) -> 0 | O37: =IF(O33=0,0,IF($T$11<=Input!O21,0,N36+N37)) -> 0 | ... R37: =IF(R33=0,0,IF($T$11<=Input!R21,0,Q36+Q37)) -> 0 | T37: =SUM(G36:R36) -> 0 | U37: =SUM(G38:R38) -> 0 | V37: =SUM(T37,U37) -> 0
A38: 35886 | B38: =Input!G$22 -> 0 | E38: 0.12 | F38: Interest amount | G38: =G37/12*$E38 -> 0 | H38: =H37/12*$E38 -> 0 | I38: =I37/12*$E38 -> 0 | J38: =J37/12*$E38 -> 0 | K38: =K37/12*$E38 -> 0 | L38: =L37/12*$E38 -> 0 | M38: =M37/12*$E38 -> 0 | N38: =N37/12*$E38 -> 0 | ... R38: =R37/12*$E38 -> 0 | S38: =SUM(G38:R38) -> 0 | T38: =SUM(T19,T25,T31,T37) -> 0 | U38: =SUM(U19,U25,U31,U37) -> 0 | V38: =SUM(V19,V25,V31,V37) -> 0
A39: 35916 | B39: =Input!H$22 -> 0 | D39: 5 | E39: 1999-2000 | F39: PF'able Salary | G39: 36251 | H39: 36281 | I39: 36312 | J39: 36342 | K39: 36373 | L39: 36404 | M39: 36434 | N39: 36465 | O39: 36495 | P39: 36526 | Q39: 36557 | R39: 36586 | S39: =SUM(Input!G24:R24) -> 0
A40: 35947 | B40: =Input!I$22 -> 0 | F40: 8.33% of PF'able Salary | G40: =IF(Input!G24=0,0,INT((Input!G24*8.33/100)+0.5)) -> 0 | H40: =IF(Input!H24=0,0,INT((Input!H24*8.33/100)+0.5)) -> 0 | I40: =IF(Input!I24=0,0,INT((Input!I24*8.33/100)+0.5)) -> 0 | J40: =IF(Input!J24=0,0,INT((Input!J24*8.33/100)+0.5)) -> 0 | K40: =IF(Input!K24=0,0,INT((Input!K24*8.33/100)+0.5)) -> 0 | L40: =IF(Input!L24=0,0,INT((Input!L24*8.33/100)+0.5)) -> 0 | M40: =IF(Input!M24=0,0,INT((Input!M24*8.33/100)+0.5)) -> 0 | N40: =IF(Input!N24=0,0,INT((Input!N24*8.33/100)+0.5)) -> 0 | ... R40: =IF(Input!R24=0,0,INT((Input!R24*8.33/100)+0.5)) -> 0 | S40: =SUM(G40:R40) -> 0
...

Sheet Output & Statistics
B2: EPS 1995 Pension - Output & Statistics (Ratios)
B3: Developed by Mr. Neeraj Bhargava (9950826109) in consultation with Mr. Parveen Kohli (9810306699) & with technical support from Mr. C Ramasamy
B5: Name | H5: :: | I5: =Input!K8 -> VARRINDER KAUR RAINA
B6: Date of Commencement of Ceiling Salary Pension | H6: :: | I6: =Input!I11 -> 43586
B7: Date of Commencement of Actual Salary Pension | H7: :: | I7: =Input!O11 -> 43586
B9: Output | I9: Statistics (Ratios)
B11: Superannuated Pension | C11: Amount type | D11: From | E11: To | F11: S No | G11: Amount in Rs. | I11: Ratios | J11: S No | K11: Value
C12: Ceiling Salary Pension | F12: 1 | G12: =IF('Pension Cal'!Q32=0,'Pension Cal'!M46,0) -> 3531 | I12: Increase in Pension Amount (in numbers) | J12: 2/1 | K12: =IF('Pension Cal'!Q32<=0,G13/G12,0) -> 6.8408383
C13: Actual Salary Pension | F13: 2 | G13: =IF('Pension Cal'!Q32=0,'Pension Cal'!R46,0) -> 24155 | I13: Difference between Proposed commencement of actual salary pension and Start of ceiling salary pension (in months) | J13: 9 | K13: =IF('Pension Cal'!Q32<=0,('Amount Cal'!T11-'Amount Cal'!I11)/30,0) -> -1.0333333
C14: Increase in Pension (Difference in Actual Salary & Ceiling Amount Pension) | F14: 2-1 | G14: =G13-G12 -> 20624
C16: Differential contribution | D16: =IF(G12=0,0,'Pension Cal'!F9) -> 35019 | E16: =IF(G12=0,0,'Amount Cal'!G11) -> 43586 | F16: 3 | G16: =IF(G12=0,0,MAX('Amount Cal'!T20:T198)) -> 691316.26 | I16: Differential contribution / Differential contribution with total interest (in %) | J16: 3/3+6 | K16: =IF('Pension Cal'!Q32<=0,G16/G21,0) -> 0.74902544
C17: Additional amount Paid for 1.16% Govt share after 01-09-2014 | D17: =IF(G12=0,0,'Pension Cal'!F11) -> 41883 | E17: =IF(G12=0,0,'Amount Cal'!G11) -> 43586 | F17: 4 | G17: =IF(AND(G12=0,Input!I10>'Pension Cal'!F11),0,SUM('Amount Cal'!S132,'Amount Cal'!S139,'Amount Cal'!S146,'Amount Cal'!S153,'Amount Cal'!S160,'Amount Cal'!S174,'Amount Cal'!S181,'Amount Cal'!S188,'Amount Cal'!S195)) -> 54507 | I17: Additional amount / Differential contribution with total interest (in %) | J17: 4/3+6 | K17: =IF('Pension Cal'!Q32<=0,G17/G21,0) -> 0.059057094
C18: Interest on differential contribution | D18: =IF(G12=0,0,'Pension Cal'!F9) -> 35019 | E18: =IF(G12=0,0,'Amount Cal'!G11) -> 43586 | F18: 5 | G18: =IF(G12=0,0,VLOOKUP((MAX('Amount Cal'!T20:'Amount Cal'!T191)),('Amount Cal'!T20:'Amount Cal'!U198),2,FALSE)) -> 231638.05 | I18: Interest till date of retirement / Differential contribution with total interest (in %) | J18: 5/3+6 | K18: =IF('Pension Cal'!Q32<=0,G18/G21,0) -> 0.25097456
C19: Interest on differential contribution & interest | D19: =IF(G12=0,0,'Amount Cal'!I11) -> 43617 | E19: =IF(G12=0,0,I7) -> 43586 | F19: 5-6 | G19: =G20-G18 -> 0 | I19: Interest on differential contribution & interest / Differential contribution with total interest (in %) | J19: 5-6/3+6 | K19: =IF('Pension Cal'!Q32<=0,G19/G21,0) -> 0
C20: Total Interest | D20: =IF(G12=0,0,'Pension Cal'!F9) -> 35019 | E20: =IF(G12=0,0,I7) -> 43586 | F20: 6 | G20: =IF(G12=0,0,MAX('Amount Cal'!U20:'Amount Cal'!U191)) -> 231638.05 | I20: Total Interest / Differential contribution with total Interest (in %) | J20: 6/3+6 | K20: =IF('Pension Cal'!Q32<=0,G20/G21,0) -> 0.25097456
C21: Differential Contribution with Total Interest | F21: 3+6 | G21: =SUM(G16,G20) -> 922954.31
C22: Total to pay to EPFO | F22: 4+3+6 | G22: =SUM(G17,G21) -> 977461.31
C24: Pension Revision Arrear (without interest) | F24: 7 | G24: =IF(G12=0,0,G14*K13) -> -21311.467 | I24: Balance amount will be recovered (in months) * | J24: 3+6-7/ 2-1 | K24: =IF(G21-G24<=0,0,INT(G21-G24)/G14) -> 45.784765
I25: Pension Arrear / Payment to EPFO (in numbers) | J25: 7/ 4+3+6 | K25: =IF('Pension Cal'!Q32<=0,G24/G22,0) -> -0.021802875
C27: Average 12/60 months salary | F27: 8 | G27: =IF(G12=0,0,IF(Input!I10<'Pension Cal'!F11,'Pension Cal'!V37,'Pension Cal'!W37)) -> 86909.967 | I27: Actual Salary Pension / 60 months average salary (in %) | J27: 2/8 | K27: =IF(G12=0,0,G13/G27) -> 0.2779313
I28: Differential contribution with Interest / 60 months average salary (in numbers) | J28: 3+6/8 | K28: =IF(G12=0,0,G21/G27) -> 10.61966
I29: Pension Revision Arrears without interest / 60 months average salary (in numbers) ** | J29: 7/8 | K29: =IF(G12=0,0,G24/G27) -> -0.24521315
B31: Reduceded Pension | C31: Amount type | D31: From | E31: To | F31: S No | G31: Amount in Rs. | I31: Ratios | J31: S No | K31: Value
C32: Ceiling Salary Pension | F32: 1 | G32: =IF('Pension Cal'!I13<'Pension Cal'!I12,'Pension Cal'!M51,0) -> 0 | I32: Increase in Pension Amount (in numbers) | J32: 2/1 | K32: =IF(G32=0,0,G33/G32) -> 0
C33: Actual Salary Pension | F33: 2 | G33: =IF('Pension Cal'!I13<'Pension Cal'!I12,'Pension Cal'!R51,0) -> 0 | I33: Difference between Proposed commencement of actual salary pension and Start of ceiling salary pension (in months) | J33: 9 | K33: =IF(G32=0,0,('Amount Cal'!T11-'Amount Cal'!I11)/30) -> 0
C34: Increase in Pension (Difference in Actual Salary & Ceiling Amount Pension) | F34: 2-1 | G34: =G33-G32 -> 0
C36: Differential contribution | D36: =IF(G32=0,0,'Pension Cal'!F9) -> 0 | E36: =IF(G32=0,0,'Amount Cal'!M11) -> 0 | F36: 3 | G36: =IF(G32=0,0,MAX('Amount Cal'!T20:T198)) -> 0 | I36: Differential contribution / Differential contribution with interest (in %) | J36: 3/3+6 | K36: =IF(G32=0,0,G36/G41) -> 0
C37: Additional amount Paid for 1.16% Govt share after 01-09-2014 | D37: =IF(G32=0,0,'Pension Cal'!F11) -> 0 | E37: =IF(G32=0,0,'Amount Cal'!T11) -> 0 | F37: 4 | G37: =IF(AND(G32=0,Input!I10>'Pension Cal'!F11),0,SUM('Amount Cal'!S132,'Amount Cal'!S139,'Amount Cal'!S146,'Amount Cal'!S153,'Amount Cal'!S160,'Amount Cal'!S174,'Amount Cal'!S181,'Amount Cal'!S188,'Amount Cal'!S195)) -> 0 | I37: Additional amount / Differential contribution with interest (in %) | J37: 4/3+6 | K37: =IF(G32=0,0,G37/G41) -> 0
C38: Interest on differential contribution | D38: =IF(G32=0,0,'Pension Cal'!F9) -> 0 | E38: =IF(G32=0,0,'Amount Cal'!M11) -> 0 | F38: 5 | G38: =IF(G32=0,0,VLOOKUP((MAX('Amount Cal'!T20:'Amount Cal'!T198)),('Amount Cal'!T20:'Amount Cal'!U198),2,FALSE)) -> 0 | I38: Interest till date of retirement / Differential contribution with interest (in %) | J38: 5/3+6 | K38: =IF(G32=0,0,G38/G41) -> 0
C39: Interest on differential contribution & interest | D39: =IF(G32=0,0,'Amount Cal'!O11) -> 0 | E39: =IF(G32=0,0,I29) -> 0 | F39: 5-6 | G39: =G40-G38 -> 0 | I39: Differential contribution / Differential contribution with interest (in %) | J39: 5-6/3+6 | K39: =IF(G32=0,0,G39/G41) -> 0
C40: Total Interest | D40: =IF(G32=0,0,'Pension Cal'!F9) -> 0 | E40: =IF(G32=0,0,I29) -> 0 | F40: 6 | G40: =IF(G32=0,0,MAX('Amount Cal'!U20:'Amount Cal'!U198)) -> 0 | I40: Total Interest / Differential contribution with Interest (in %) | J40: 6/3+6 | K40: =IF(G32=0,0,G40/G41) -> 0
C41: Differential contribution with Interest | F41: 3+6 | G41: =SUM(G36,G40) -> 0
C42: Total to pay to EPFO | F42: 4+3+6 | G42: =SUM(G37,G41) -> 0
C44: Pension Revision Arrear (without interest) | F44: 7 | G44: =IF(G32=0,0,G34*K33) -> 0 | I44: Balance amount will be recovered (in months) * | J44: 3+6-7/ 2-1 | K44: =IF(G41-G44<=0,0,INT(G41-G44)/G34) -> 0
I45: Pension Arrear / Payment to EPFO (in numbers) | J45: 7/ 4+3+6 | K45: =IF(G32=0,0,G44/G42) -> 0
C47: Average 12/60 months salary | F47: 8 | G47: =IF(G32=0,0,IF(Input!I10<'Pension Cal'!F11,'Pension Cal'!V37,'Pension Cal'!W37)) -> 0 | I47: Actual Salary Pension / 60 months average salary (in %) | J47: 2/8 | K47: =IF(G32=0,0,G33/G47) -> 0
I48: Differential contribution with Interest / 60 months average salary (in numbers) | J48: 3+6/8 | K48: =IF(G32=0,0,G41/G47) -> 0
I49: Pension Revision Arrears without interest / 60 months average salary (in numbers) ** | J49: 7/8 | K49: =IF(G32=0,0,G44/G47) -> 0
B51: Enhanced Pension | C51: Amount type | F51: S No | G51: Amount in Rs. | I51: Ratios | J51: S No | K51: Value
C52: Ceiling Salary Pension | F52: 1 | G52: =IF('Pension Cal'!I13<'Pension Cal'!I12,0,'Pension Cal'!M52) -> 0 | I52: Increase in Pension Amount (in numbers) | J52: 2/1 | K52: =IF(G52=0,0,G53/G52) -> 0
...
